Internal Server Error: /user/invitation/2a3f29f8-d1b9-4de2-8096-fb4725c34d92/
Traceback (most recent call last):
  File "/home/siew/venvs/djmatch/lib/python3.5/site-packages/django/core/handlers/exception.py", line 41, in inner
    response = get_response(request)
  File "/home/siew/venvs/djmatch/lib/python3.5/site-packages/django/core/handlers/base.py", line 187, in _get_response
    response = self.process_exception_by_middleware(e, request)
  File "/home/siew/venvs/djmatch/lib/python3.5/site-packages/django/core/handlers/base.py", line 185, in _get_response
    response = wrapped_callback(request, *callback_args, **callback_kwargs)
  File "/home/siew/venvs/djmatch/lib/python3.5/site-packages/django/views/generic/base.py", line 68, in view
    return self.dispatch(request, *args, **kwargs)
  File "/home/siew/venvs/djmatch/lib/python3.5/site-packages/django/views/generic/base.py", line 88, in dispatch
    return handler(request, *args, **kwargs)
  File "/home/siew/venvs/djmatch/lib/python3.5/site-packages/django/views/generic/edit.py", line 217, in post
    return super(BaseCreateView, self).post(request, *args, **kwargs)
  File "/home/siew/venvs/djmatch/lib/python3.5/site-packages/django/views/generic/edit.py", line 183, in post
    return self.form_valid(form)
  File "/home/siew/djmatch/src/user/views/staffs.py", line 33, in form_valid
    obj = form.save(commit=True)
  File "/home/siew/djmatch/src/user/forms.py", line 78, in save
    subscribe = self.cleaned_data["subscribe"]
KeyError: 'subscribe'
"POST /user/invitation/2a3f29f8-d1b9-4de2-8096-fb4725c34d92/ HTTP/1.1" 500 106554
Internal Server Error: /user/invitation/2a3f29f8-d1b9-4de2-8096-fb4725c34d92/
Traceback (most recent call last):
  File "/home/siew/venvs/djmatch/lib/python3.5/site-packages/django/core/handlers/exception.py", line 41, in inner
    response = get_response(request)
  File "/home/siew/venvs/djmatch/lib/python3.5/site-packages/django/core/handlers/base.py", line 187, in _get_response
    response = self.process_exception_by_middleware(e, request)
  File "/home/siew/venvs/djmatch/lib/python3.5/site-packages/django/core/handlers/base.py", line 185, in _get_response
    response = wrapped_callback(request, *callback_args, **callback_kwargs)
  File "/home/siew/venvs/djmatch/lib/python3.5/site-packages/django/views/generic/base.py", line 68, in view
    return self.dispatch(request, *args, **kwargs)
  File "/home/siew/venvs/djmatch/lib/python3.5/site-packages/django/views/generic/base.py", line 88, in dispatch
    return handler(request, *args, **kwargs)
  File "/home/siew/venvs/djmatch/lib/python3.5/site-packages/django/views/generic/edit.py", line 217, in post
    return super(BaseCreateView, self).post(request, *args, **kwargs)
  File "/home/siew/venvs/djmatch/lib/python3.5/site-packages/django/views/generic/edit.py", line 183, in post
    return self.form_valid(form)
  File "/home/siew/djmatch/src/user/views/staffs.py", line 33, in form_valid
    obj = form.save(commit=True)
  File "/home/siew/djmatch/src/user/forms.py", line 78, in save
    subscribe = self.cleaned_data["subscribe"]
KeyError: 'subscribe'
"POST /user/invitation/2a3f29f8-d1b9-4de2-8096-fb4725c34d92/ HTTP/1.1" 500 106556
Internal Server Error: /user/invitation/2a3f29f8-d1b9-4de2-8096-fb4725c34d92/
Traceback (most recent call last):
  File "/home/siew/venvs/djmatch/lib/python3.5/site-packages/django/core/handlers/exception.py", line 41, in inner
    response = get_response(request)
  File "/home/siew/venvs/djmatch/lib/python3.5/site-packages/django/core/handlers/base.py", line 187, in _get_response
    response = self.process_exception_by_middleware(e, request)
  File "/home/siew/venvs/djmatch/lib/python3.5/site-packages/django/core/handlers/base.py", line 185, in _get_response
    response = wrapped_callback(request, *callback_args, **callback_kwargs)
  File "/home/siew/venvs/djmatch/lib/python3.5/site-packages/django/views/generic/base.py", line 68, in view
    return self.dispatch(request, *args, **kwargs)
  File "/home/siew/venvs/djmatch/lib/python3.5/site-packages/django/views/generic/base.py", line 88, in dispatch
    return handler(request, *args, **kwargs)
  File "/home/siew/venvs/djmatch/lib/python3.5/site-packages/django/views/generic/edit.py", line 217, in post
    return super(BaseCreateView, self).post(request, *args, **kwargs)
  File "/home/siew/venvs/djmatch/lib/python3.5/site-packages/django/views/generic/edit.py", line 183, in post
    return self.form_valid(form)
  File "/home/siew/djmatch/src/user/views/staffs.py", line 33, in form_valid
    obj = form.save(commit=True)
  File "/home/siew/djmatch/src/user/forms.py", line 78, in save
    subscribe = self.cleaned_data["subscribe"]
KeyError: 'subscribe'
"POST /user/invitation/2a3f29f8-d1b9-4de2-8096-fb4725c34d92/ HTTP/1.1" 500 106556
Internal Server Error: /user/invitation/2a3f29f8-d1b9-4de2-8096-fb4725c34d92/
Traceback (most recent call last):
  File "/home/siew/venvs/djmatch/lib/python3.5/site-packages/django/core/handlers/exception.py", line 41, in inner
    response = get_response(request)
  File "/home/siew/venvs/djmatch/lib/python3.5/site-packages/django/core/handlers/base.py", line 187, in _get_response
    response = self.process_exception_by_middleware(e, request)
  File "/home/siew/venvs/djmatch/lib/python3.5/site-packages/django/core/handlers/base.py", line 185, in _get_response
    response = wrapped_callback(request, *callback_args, **callback_kwargs)
  File "/home/siew/venvs/djmatch/lib/python3.5/site-packages/django/views/generic/base.py", line 68, in view
    return self.dispatch(request, *args, **kwargs)
  File "/home/siew/venvs/djmatch/lib/python3.5/site-packages/django/views/generic/base.py", line 88, in dispatch
    return handler(request, *args, **kwargs)
  File "/home/siew/venvs/djmatch/lib/python3.5/site-packages/django/views/generic/edit.py", line 217, in post
    return super(BaseCreateView, self).post(request, *args, **kwargs)
  File "/home/siew/venvs/djmatch/lib/python3.5/site-packages/django/views/generic/edit.py", line 183, in post
    return self.form_valid(form)
  File "/home/siew/djmatch/src/user/views/staffs.py", line 33, in form_valid
    obj = form.save(commit=True)
  File "/home/siew/djmatch/src/user/forms.py", line 78, in save
    subscribe = self.cleaned_data["subscribe"]
KeyError: 'subscribe'
"POST /user/invitation/2a3f29f8-d1b9-4de2-8096-fb4725c34d92/ HTTP/1.1" 500 106556
Internal Server Error: /user/invitation/2a3f29f8-d1b9-4de2-8096-fb4725c34d92/
Traceback (most recent call last):
  File "/home/siew/venvs/djmatch/lib/python3.5/site-packages/django/core/handlers/exception.py", line 41, in inner
    response = get_response(request)
  File "/home/siew/venvs/djmatch/lib/python3.5/site-packages/django/core/handlers/base.py", line 187, in _get_response
    response = self.process_exception_by_middleware(e, request)
  File "/home/siew/venvs/djmatch/lib/python3.5/site-packages/django/core/handlers/base.py", line 185, in _get_response
    response = wrapped_callback(request, *callback_args, **callback_kwargs)
  File "/home/siew/venvs/djmatch/lib/python3.5/site-packages/django/views/generic/base.py", line 68, in view
    return self.dispatch(request, *args, **kwargs)
  File "/home/siew/venvs/djmatch/lib/python3.5/site-packages/django/views/generic/base.py", line 88, in dispatch
    return handler(request, *args, **kwargs)
  File "/home/siew/venvs/djmatch/lib/python3.5/site-packages/django/views/generic/edit.py", line 217, in post
    return super(BaseCreateView, self).post(request, *args, **kwargs)
  File "/home/siew/venvs/djmatch/lib/python3.5/site-packages/django/views/generic/edit.py", line 183, in post
    return self.form_valid(form)
  File "/home/siew/djmatch/src/user/views/staffs.py", line 33, in form_valid
    obj = form.save(commit=True)
  File "/home/siew/djmatch/src/user/forms.py", line 78, in save
    subscribe = self.cleaned_data["subscribe"]
KeyError: 'subscribe'
"POST /user/invitation/2a3f29f8-d1b9-4de2-8096-fb4725c34d92/ HTTP/1.1" 500 106556
Internal Server Error: /user/invitation/2a3f29f8-d1b9-4de2-8096-fb4725c34d92/
Traceback (most recent call last):
  File "/home/siew/venvs/djmatch/lib/python3.5/site-packages/django/core/handlers/exception.py", line 41, in inner
    response = get_response(request)
  File "/home/siew/venvs/djmatch/lib/python3.5/site-packages/django/core/handlers/base.py", line 187, in _get_response
    response = self.process_exception_by_middleware(e, request)
  File "/home/siew/venvs/djmatch/lib/python3.5/site-packages/django/core/handlers/base.py", line 185, in _get_response
    response = wrapped_callback(request, *callback_args, **callback_kwargs)
  File "/home/siew/venvs/djmatch/lib/python3.5/site-packages/django/views/generic/base.py", line 68, in view
    return self.dispatch(request, *args, **kwargs)
  File "/home/siew/venvs/djmatch/lib/python3.5/site-packages/django/views/generic/base.py", line 88, in dispatch
    return handler(request, *args, **kwargs)
  File "/home/siew/venvs/djmatch/lib/python3.5/site-packages/django/views/generic/edit.py", line 217, in post
    return super(BaseCreateView, self).post(request, *args, **kwargs)
  File "/home/siew/venvs/djmatch/lib/python3.5/site-packages/django/views/generic/edit.py", line 183, in post
    return self.form_valid(form)
  File "/home/siew/djmatch/src/user/views/staffs.py", line 33, in form_valid
    obj = form.save(commit=True)
  File "/home/siew/djmatch/src/user/forms.py", line 78, in save
    subscribe = self.cleaned_data["subscribe"]
KeyError: 'subscribe'
"POST /user/invitation/2a3f29f8-d1b9-4de2-8096-fb4725c34d92/ HTTP/1.1" 500 106556
Internal Server Error: /user/invitation/2a3f29f8-d1b9-4de2-8096-fb4725c34d92/
Traceback (most recent call last):
  File "/home/siew/venvs/djmatch/lib/python3.5/site-packages/django/core/handlers/exception.py", line 41, in inner
    response = get_response(request)
  File "/home/siew/venvs/djmatch/lib/python3.5/site-packages/django/core/handlers/base.py", line 187, in _get_response
    response = self.process_exception_by_middleware(e, request)
  File "/home/siew/venvs/djmatch/lib/python3.5/site-packages/django/core/handlers/base.py", line 185, in _get_response
    response = wrapped_callback(request, *callback_args, **callback_kwargs)
  File "/home/siew/venvs/djmatch/lib/python3.5/site-packages/django/views/generic/base.py", line 68, in view
    return self.dispatch(request, *args, **kwargs)
  File "/home/siew/venvs/djmatch/lib/python3.5/site-packages/django/views/generic/base.py", line 88, in dispatch
    return handler(request, *args, **kwargs)
  File "/home/siew/venvs/djmatch/lib/python3.5/site-packages/django/views/generic/edit.py", line 217, in post
    return super(BaseCreateView, self).post(request, *args, **kwargs)
  File "/home/siew/venvs/djmatch/lib/python3.5/site-packages/django/views/generic/edit.py", line 183, in post
    return self.form_valid(form)
  File "/home/siew/djmatch/src/user/views/staffs.py", line 33, in form_valid
    obj = form.save(commit=True)
  File "/home/siew/djmatch/src/user/forms.py", line 78, in save
    subscribe = self.cleaned_data["subscribe"]
KeyError: 'subscribe'
"POST /user/invitation/2a3f29f8-d1b9-4de2-8096-fb4725c34d92/ HTTP/1.1" 500 106556
Internal Server Error: /user/invitation/2a3f29f8-d1b9-4de2-8096-fb4725c34d92/
Traceback (most recent call last):
  File "/home/siew/venvs/djmatch/lib/python3.5/site-packages/django/core/handlers/exception.py", line 41, in inner
    response = get_response(request)
  File "/home/siew/venvs/djmatch/lib/python3.5/site-packages/django/core/handlers/base.py", line 187, in _get_response
    response = self.process_exception_by_middleware(e, request)
  File "/home/siew/venvs/djmatch/lib/python3.5/site-packages/django/core/handlers/base.py", line 185, in _get_response
    response = wrapped_callback(request, *callback_args, **callback_kwargs)
  File "/home/siew/venvs/djmatch/lib/python3.5/site-packages/django/views/generic/base.py", line 68, in view
    return self.dispatch(request, *args, **kwargs)
  File "/home/siew/venvs/djmatch/lib/python3.5/site-packages/django/views/generic/base.py", line 88, in dispatch
    return handler(request, *args, **kwargs)
  File "/home/siew/venvs/djmatch/lib/python3.5/site-packages/django/views/generic/edit.py", line 217, in post
    return super(BaseCreateView, self).post(request, *args, **kwargs)
  File "/home/siew/venvs/djmatch/lib/python3.5/site-packages/django/views/generic/edit.py", line 183, in post
    return self.form_valid(form)
  File "/home/siew/djmatch/src/user/views/staffs.py", line 33, in form_valid
    obj = form.save(commit=True)
  File "/home/siew/djmatch/src/user/forms.py", line 78, in save
    subscribe = self.cleaned_data["subscribe"]
KeyError: 'subscribe'
"POST /user/invitation/2a3f29f8-d1b9-4de2-8096-fb4725c34d92/ HTTP/1.1" 500 106556
Internal Server Error: /project/create/
Traceback (most recent call last):
  File "/home/siew/venvs/djmatch/lib/python3.5/site-packages/django/core/handlers/exception.py", line 41, in inner
    response = get_response(request)
  File "/home/siew/venvs/djmatch/lib/python3.5/site-packages/django/core/handlers/base.py", line 187, in _get_response
    response = self.process_exception_by_middleware(e, request)
  File "/home/siew/venvs/djmatch/lib/python3.5/site-packages/django/core/handlers/base.py", line 185, in _get_response
    response = wrapped_callback(request, *callback_args, **callback_kwargs)
  File "/home/siew/venvs/djmatch/lib/python3.5/site-packages/django/views/generic/base.py", line 68, in view
    return self.dispatch(request, *args, **kwargs)
  File "/home/siew/venvs/djmatch/lib/python3.5/site-packages/django/contrib/auth/mixins.py", line 56, in dispatch
    return super(LoginRequiredMixin, self).dispatch(request, *args, **kwargs)
  File "/home/siew/venvs/djmatch/lib/python3.5/site-packages/django/contrib/auth/mixins.py", line 116, in dispatch
    return super(UserPassesTestMixin, self).dispatch(request, *args, **kwargs)
  File "/home/siew/venvs/djmatch/lib/python3.5/site-packages/django/views/generic/base.py", line 88, in dispatch
    return handler(request, *args, **kwargs)
  File "/home/siew/venvs/djmatch/lib/python3.5/site-packages/django/views/generic/edit.py", line 217, in post
    return super(BaseCreateView, self).post(request, *args, **kwargs)
  File "/home/siew/venvs/djmatch/lib/python3.5/site-packages/django/views/generic/edit.py", line 183, in post
    return self.form_valid(form)
  File "/home/siew/djmatch/src/project/views.py", line 169, in form_valid
    new_organization = Organization.objects.create(title=company,type=2,status=True)
NameError: name 'company' is not defined
"POST /project/create/ HTTP/1.1" 500 110184
Internal Server Error: /project/create/
Traceback (most recent call last):
  File "/home/siew/venvs/djmatch/lib/python3.5/site-packages/django/core/handlers/exception.py", line 41, in inner
    response = get_response(request)
  File "/home/siew/venvs/djmatch/lib/python3.5/site-packages/django/core/handlers/base.py", line 187, in _get_response
    response = self.process_exception_by_middleware(e, request)
  File "/home/siew/venvs/djmatch/lib/python3.5/site-packages/django/core/handlers/base.py", line 185, in _get_response
    response = wrapped_callback(request, *callback_args, **callback_kwargs)
  File "/home/siew/venvs/djmatch/lib/python3.5/site-packages/django/views/generic/base.py", line 68, in view
    return self.dispatch(request, *args, **kwargs)
  File "/home/siew/venvs/djmatch/lib/python3.5/site-packages/django/contrib/auth/mixins.py", line 56, in dispatch
    return super(LoginRequiredMixin, self).dispatch(request, *args, **kwargs)
  File "/home/siew/venvs/djmatch/lib/python3.5/site-packages/django/contrib/auth/mixins.py", line 116, in dispatch
    return super(UserPassesTestMixin, self).dispatch(request, *args, **kwargs)
  File "/home/siew/venvs/djmatch/lib/python3.5/site-packages/django/views/generic/base.py", line 88, in dispatch
    return handler(request, *args, **kwargs)
  File "/home/siew/venvs/djmatch/lib/python3.5/site-packages/django/views/generic/edit.py", line 217, in post
    return super(BaseCreateView, self).post(request, *args, **kwargs)
  File "/home/siew/venvs/djmatch/lib/python3.5/site-packages/django/views/generic/edit.py", line 183, in post
    return self.form_valid(form)
  File "/home/siew/djmatch/src/project/views.py", line 170, in form_valid
    project.company = new_company
NameError: name 'new_company' is not defined
"POST /project/create/ HTTP/1.1" 500 110309
Internal Server Error: /project/create/
Traceback (most recent call last):
  File "/home/siew/venvs/djmatch/lib/python3.5/site-packages/django/db/backends/utils.py", line 65, in execute
    return self.cursor.execute(sql, params)
  File "/home/siew/venvs/djmatch/lib/python3.5/site-packages/django/db/backends/sqlite3/base.py", line 328, in execute
    return Database.Cursor.execute(self, query, params)
sqlite3.IntegrityError: UNIQUE constraint failed: project_organization.title

The above exception was the direct cause of the following exception:

Traceback (most recent call last):
  File "/home/siew/venvs/djmatch/lib/python3.5/site-packages/django/core/handlers/exception.py", line 41, in inner
    response = get_response(request)
  File "/home/siew/venvs/djmatch/lib/python3.5/site-packages/django/core/handlers/base.py", line 187, in _get_response
    response = self.process_exception_by_middleware(e, request)
  File "/home/siew/venvs/djmatch/lib/python3.5/site-packages/django/core/handlers/base.py", line 185, in _get_response
    response = wrapped_callback(request, *callback_args, **callback_kwargs)
  File "/home/siew/venvs/djmatch/lib/python3.5/site-packages/django/views/generic/base.py", line 68, in view
    return self.dispatch(request, *args, **kwargs)
  File "/home/siew/venvs/djmatch/lib/python3.5/site-packages/django/contrib/auth/mixins.py", line 56, in dispatch
    return super(LoginRequiredMixin, self).dispatch(request, *args, **kwargs)
  File "/home/siew/venvs/djmatch/lib/python3.5/site-packages/django/contrib/auth/mixins.py", line 116, in dispatch
    return super(UserPassesTestMixin, self).dispatch(request, *args, **kwargs)
  File "/home/siew/venvs/djmatch/lib/python3.5/site-packages/django/views/generic/base.py", line 88, in dispatch
    return handler(request, *args, **kwargs)
  File "/home/siew/venvs/djmatch/lib/python3.5/site-packages/django/views/generic/edit.py", line 217, in post
    return super(BaseCreateView, self).post(request, *args, **kwargs)
  File "/home/siew/venvs/djmatch/lib/python3.5/site-packages/django/views/generic/edit.py", line 183, in post
    return self.form_valid(form)
  File "/home/siew/djmatch/src/project/views.py", line 169, in form_valid
    new_organization = Organization.objects.create(title=organization,type=2,status=True)
  File "/home/siew/venvs/djmatch/lib/python3.5/site-packages/django/db/models/manager.py", line 85, in manager_method
    return getattr(self.get_queryset(), name)(*args, **kwargs)
  File "/home/siew/venvs/djmatch/lib/python3.5/site-packages/django/db/models/query.py", line 394, in create
    obj.save(force_insert=True, using=self.db)
  File "/home/siew/venvs/djmatch/lib/python3.5/site-packages/django/db/models/base.py", line 807, in save
    force_update=force_update, update_fields=update_fields)
  File "/home/siew/venvs/djmatch/lib/python3.5/site-packages/django/db/models/base.py", line 837, in save_base
    updated = self._save_table(raw, cls, force_insert, force_update, using, update_fields)
  File "/home/siew/venvs/djmatch/lib/python3.5/site-packages/django/db/models/base.py", line 923, in _save_table
    result = self._do_insert(cls._base_manager, using, fields, update_pk, raw)
  File "/home/siew/venvs/djmatch/lib/python3.5/site-packages/django/db/models/base.py", line 962, in _do_insert
    using=using, raw=raw)
  File "/home/siew/venvs/djmatch/lib/python3.5/site-packages/django/db/models/manager.py", line 85, in manager_method
    return getattr(self.get_queryset(), name)(*args, **kwargs)
  File "/home/siew/venvs/djmatch/lib/python3.5/site-packages/django/db/models/query.py", line 1076, in _insert
    return query.get_compiler(using=using).execute_sql(return_id)
  File "/home/siew/venvs/djmatch/lib/python3.5/site-packages/django/db/models/sql/compiler.py", line 1107, in execute_sql
    cursor.execute(sql, params)
  File "/home/siew/venvs/djmatch/lib/python3.5/site-packages/django/db/backends/utils.py", line 80, in execute
    return super(CursorDebugWrapper, self).execute(sql, params)
  File "/home/siew/venvs/djmatch/lib/python3.5/site-packages/django/db/backends/utils.py", line 65, in execute
    return self.cursor.execute(sql, params)
  File "/home/siew/venvs/djmatch/lib/python3.5/site-packages/django/db/utils.py", line 94, in __exit__
    six.reraise(dj_exc_type, dj_exc_value, traceback)
  File "/home/siew/venvs/djmatch/lib/python3.5/site-packages/django/utils/six.py", line 685, in reraise
    raise value.with_traceback(tb)
  File "/home/siew/venvs/djmatch/lib/python3.5/site-packages/django/db/backends/utils.py", line 65, in execute
    return self.cursor.execute(sql, params)
  File "/home/siew/venvs/djmatch/lib/python3.5/site-packages/django/db/backends/sqlite3/base.py", line 328, in execute
    return Database.Cursor.execute(self, query, params)
django.db.utils.IntegrityError: UNIQUE constraint failed: project_organization.title
"POST /project/create/ HTTP/1.1" 500 189712
Internal Server Error: /project/ajax/getDetailRecommendations/
Traceback (most recent call last):
  File "/home/siew/venvs/djmatch/lib/python3.5/site-packages/django/core/handlers/exception.py", line 41, in inner
    response = get_response(request)
  File "/home/siew/venvs/djmatch/lib/python3.5/site-packages/django/core/handlers/base.py", line 187, in _get_response
    response = self.process_exception_by_middleware(e, request)
  File "/home/siew/venvs/djmatch/lib/python3.5/site-packages/django/core/handlers/base.py", line 185, in _get_response
    response = wrapped_callback(request, *callback_args, **callback_kwargs)
  File "/home/siew/djmatch/src/project/views.py", line 34, in AjaxGetDetailRecommendations
    return JsonResponse({"keywords" : list(k)},status=200)
UnboundLocalError: local variable 'k' referenced before assignment
"GET /project/ajax/getDetailRecommendations/?id=3 HTTP/1.1" 500 21311
