Internal Server Error: /user/resend-activation/
Traceback (most recent call last):
  File "/home/siew/venvs/lib/python3.5/site-packages/django/core/handlers/exception.py", line 41, in inner
    response = get_response(request)
  File "/home/siew/venvs/lib/python3.5/site-packages/django/core/handlers/base.py", line 187, in _get_response
    response = self.process_exception_by_middleware(e, request)
  File "/home/siew/venvs/lib/python3.5/site-packages/django/core/handlers/base.py", line 185, in _get_response
    response = wrapped_callback(request, *callback_args, **callback_kwargs)
  File "/home/siew/venvs/lib/python3.5/site-packages/django/views/generic/base.py", line 68, in view
    return self.dispatch(request, *args, **kwargs)
  File "/home/siew/venvs/lib/python3.5/site-packages/django/contrib/auth/mixins.py", line 56, in dispatch
    return super(LoginRequiredMixin, self).dispatch(request, *args, **kwargs)
  File "/home/siew/venvs/lib/python3.5/site-packages/django/views/generic/base.py", line 88, in dispatch
    return handler(request, *args, **kwargs)
  File "/home/siew/venvs/lib/python3.5/site-packages/django/views/generic/edit.py", line 183, in post
    return self.form_valid(form)
  File "/home/siew/djmatch/src/user/views/views.py", line 39, in form_valid
    sendActivationEmail(activation_key,email_target)
  File "/home/siew/djmatch/src/user/views/utils.py", line 155, in sendActivationEmail
    message = "Dear Sir/Madam\n Please click on the link below \n <a href='{}'>{}</a>".format(activation_key)
IndexError: tuple index out of range
"POST /user/resend-activation/ HTTP/1.1" 500 102405
Internal Server Error: /user/resend-activation/
Traceback (most recent call last):
  File "/home/siew/venvs/lib/python3.5/site-packages/django/core/handlers/exception.py", line 41, in inner
    response = get_response(request)
  File "/home/siew/venvs/lib/python3.5/site-packages/django/core/handlers/base.py", line 187, in _get_response
    response = self.process_exception_by_middleware(e, request)
  File "/home/siew/venvs/lib/python3.5/site-packages/django/core/handlers/base.py", line 185, in _get_response
    response = wrapped_callback(request, *callback_args, **callback_kwargs)
  File "/home/siew/venvs/lib/python3.5/site-packages/django/views/generic/base.py", line 68, in view
    return self.dispatch(request, *args, **kwargs)
  File "/home/siew/venvs/lib/python3.5/site-packages/django/contrib/auth/mixins.py", line 56, in dispatch
    return super(LoginRequiredMixin, self).dispatch(request, *args, **kwargs)
  File "/home/siew/venvs/lib/python3.5/site-packages/django/views/generic/base.py", line 88, in dispatch
    return handler(request, *args, **kwargs)
  File "/home/siew/venvs/lib/python3.5/site-packages/django/views/generic/edit.py", line 183, in post
    return self.form_valid(form)
  File "/home/siew/djmatch/src/user/views/views.py", line 39, in form_valid
    sendActivationEmail(activation_key,email_target)
  File "/home/siew/djmatch/src/user/views/utils.py", line 165, in sendActivationEmail
    send_mail(subject,message,from_email,to_email,fail_silently=False,html_message=html_message)
NameError: name 'message' is not defined
"POST /user/resend-activation/ HTTP/1.1" 500 102707
Internal Server Error: /user/resend-activation/
Traceback (most recent call last):
  File "/home/siew/venvs/lib/python3.5/site-packages/django/template/base.py", line 507, in parse
    compile_func = self.tags[command]
KeyError: 'link'

During handling of the above exception, another exception occurred:

Traceback (most recent call last):
  File "/home/siew/venvs/lib/python3.5/site-packages/django/core/handlers/exception.py", line 41, in inner
    response = get_response(request)
  File "/home/siew/venvs/lib/python3.5/site-packages/django/core/handlers/base.py", line 187, in _get_response
    response = self.process_exception_by_middleware(e, request)
  File "/home/siew/venvs/lib/python3.5/site-packages/django/core/handlers/base.py", line 185, in _get_response
    response = wrapped_callback(request, *callback_args, **callback_kwargs)
  File "/home/siew/venvs/lib/python3.5/site-packages/django/views/generic/base.py", line 68, in view
    return self.dispatch(request, *args, **kwargs)
  File "/home/siew/venvs/lib/python3.5/site-packages/django/contrib/auth/mixins.py", line 56, in dispatch
    return super(LoginRequiredMixin, self).dispatch(request, *args, **kwargs)
  File "/home/siew/venvs/lib/python3.5/site-packages/django/views/generic/base.py", line 88, in dispatch
    return handler(request, *args, **kwargs)
  File "/home/siew/venvs/lib/python3.5/site-packages/django/views/generic/edit.py", line 183, in post
    return self.form_valid(form)
  File "/home/siew/djmatch/src/user/views/views.py", line 39, in form_valid
    sendActivationEmail(activation_key,email_target)
  File "/home/siew/djmatch/src/user/views/utils.py", line 158, in sendActivationEmail
    'link' : activation_key,
  File "/home/siew/venvs/lib/python3.5/site-packages/django/template/loader.py", line 67, in render_to_string
    template = get_template(template_name, using=using)
  File "/home/siew/venvs/lib/python3.5/site-packages/django/template/loader.py", line 21, in get_template
    return engine.get_template(template_name)
  File "/home/siew/venvs/lib/python3.5/site-packages/django/template/backends/django.py", line 39, in get_template
    return Template(self.engine.get_template(template_name), self)
  File "/home/siew/venvs/lib/python3.5/site-packages/django/template/engine.py", line 162, in get_template
    template, origin = self.find_template(template_name)
  File "/home/siew/venvs/lib/python3.5/site-packages/django/template/engine.py", line 136, in find_template
    name, template_dirs=dirs, skip=skip,
  File "/home/siew/venvs/lib/python3.5/site-packages/django/template/loaders/base.py", line 44, in get_template
    contents, origin, origin.template_name, self.engine,
  File "/home/siew/venvs/lib/python3.5/site-packages/django/template/base.py", line 191, in __init__
    self.nodelist = self.compile_nodelist()
  File "/home/siew/venvs/lib/python3.5/site-packages/django/template/base.py", line 230, in compile_nodelist
    return parser.parse()
  File "/home/siew/venvs/lib/python3.5/site-packages/django/template/base.py", line 509, in parse
    self.invalid_block_tag(token, command, parse_until)
  File "/home/siew/venvs/lib/python3.5/site-packages/django/template/base.py", line 571, in invalid_block_tag
    "or load this tag?" % (token.lineno, command)
django.template.exceptions.TemplateSyntaxError: Invalid block tag on line 6: 'link'. Did you forget to register or load this tag?
"POST /user/resend-activation/ HTTP/1.1" 500 155041
Internal Server Error: /admin/user/invitation/add/
Traceback (most recent call last):
  File "/home/siew/venvs/lib/python3.5/site-packages/django/core/handlers/exception.py", line 41, in inner
    response = get_response(request)
  File "/home/siew/venvs/lib/python3.5/site-packages/django/core/handlers/base.py", line 187, in _get_response
    response = self.process_exception_by_middleware(e, request)
  File "/home/siew/venvs/lib/python3.5/site-packages/django/core/handlers/base.py", line 185, in _get_response
    response = wrapped_callback(request, *callback_args, **callback_kwargs)
  File "/home/siew/venvs/lib/python3.5/site-packages/django/contrib/admin/options.py", line 551, in wrapper
    return self.admin_site.admin_view(view)(*args, **kwargs)
  File "/home/siew/venvs/lib/python3.5/site-packages/django/utils/decorators.py", line 149, in _wrapped_view
    response = view_func(request, *args, **kwargs)
  File "/home/siew/venvs/lib/python3.5/site-packages/django/views/decorators/cache.py", line 57, in _wrapped_view_func
    response = view_func(request, *args, **kwargs)
  File "/home/siew/venvs/lib/python3.5/site-packages/django/contrib/admin/sites.py", line 224, in inner
    return view(request, *args, **kwargs)
  File "/home/siew/venvs/lib/python3.5/site-packages/django/contrib/admin/options.py", line 1508, in add_view
    return self.changeform_view(request, None, form_url, extra_context)
  File "/home/siew/venvs/lib/python3.5/site-packages/django/utils/decorators.py", line 67, in _wrapper
    return bound_func(*args, **kwargs)
  File "/home/siew/venvs/lib/python3.5/site-packages/django/utils/decorators.py", line 149, in _wrapped_view
    response = view_func(request, *args, **kwargs)
  File "/home/siew/venvs/lib/python3.5/site-packages/django/utils/decorators.py", line 63, in bound_func
    return func.__get__(self, type(self))(*args2, **kwargs2)
  File "/home/siew/venvs/lib/python3.5/site-packages/django/contrib/admin/options.py", line 1408, in changeform_view
    return self._changeform_view(request, object_id, form_url, extra_context)
  File "/home/siew/venvs/lib/python3.5/site-packages/django/contrib/admin/options.py", line 1448, in _changeform_view
    self.save_model(request, new_object, form, not add)
  File "/home/siew/venvs/lib/python3.5/site-packages/django/contrib/admin/options.py", line 979, in save_model
    obj.save()
  File "/home/siew/venvs/lib/python3.5/site-packages/django/db/models/base.py", line 807, in save
    force_update=force_update, update_fields=update_fields)
  File "/home/siew/venvs/lib/python3.5/site-packages/django/db/models/base.py", line 847, in save_base
    update_fields=update_fields, raw=raw, using=using,
  File "/home/siew/venvs/lib/python3.5/site-packages/django/dispatch/dispatcher.py", line 193, in send
    for receiver in self._live_receivers(sender)
  File "/home/siew/venvs/lib/python3.5/site-packages/django/dispatch/dispatcher.py", line 193, in <listcomp>
    for receiver in self._live_receivers(sender)
  File "/home/siew/djmatch/src/user/models.py", line 80, in create_invitation
    html_message = loader.render_to_string(
NameError: name 'loader' is not defined
"POST /admin/user/invitation/add/ HTTP/1.1" 500 151055
Internal Server Error: /admin/user/invitation/add/
Traceback (most recent call last):
  File "/home/siew/venvs/lib/python3.5/site-packages/django/core/handlers/exception.py", line 41, in inner
    response = get_response(request)
  File "/home/siew/venvs/lib/python3.5/site-packages/django/core/handlers/base.py", line 187, in _get_response
    response = self.process_exception_by_middleware(e, request)
  File "/home/siew/venvs/lib/python3.5/site-packages/django/core/handlers/base.py", line 185, in _get_response
    response = wrapped_callback(request, *callback_args, **callback_kwargs)
  File "/home/siew/venvs/lib/python3.5/site-packages/django/contrib/admin/options.py", line 551, in wrapper
    return self.admin_site.admin_view(view)(*args, **kwargs)
  File "/home/siew/venvs/lib/python3.5/site-packages/django/utils/decorators.py", line 149, in _wrapped_view
    response = view_func(request, *args, **kwargs)
  File "/home/siew/venvs/lib/python3.5/site-packages/django/views/decorators/cache.py", line 57, in _wrapped_view_func
    response = view_func(request, *args, **kwargs)
  File "/home/siew/venvs/lib/python3.5/site-packages/django/contrib/admin/sites.py", line 224, in inner
    return view(request, *args, **kwargs)
  File "/home/siew/venvs/lib/python3.5/site-packages/django/contrib/admin/options.py", line 1508, in add_view
    return self.changeform_view(request, None, form_url, extra_context)
  File "/home/siew/venvs/lib/python3.5/site-packages/django/utils/decorators.py", line 67, in _wrapper
    return bound_func(*args, **kwargs)
  File "/home/siew/venvs/lib/python3.5/site-packages/django/utils/decorators.py", line 149, in _wrapped_view
    response = view_func(request, *args, **kwargs)
  File "/home/siew/venvs/lib/python3.5/site-packages/django/utils/decorators.py", line 63, in bound_func
    return func.__get__(self, type(self))(*args2, **kwargs2)
  File "/home/siew/venvs/lib/python3.5/site-packages/django/contrib/admin/options.py", line 1408, in changeform_view
    return self._changeform_view(request, object_id, form_url, extra_context)
  File "/home/siew/venvs/lib/python3.5/site-packages/django/contrib/admin/options.py", line 1448, in _changeform_view
    self.save_model(request, new_object, form, not add)
  File "/home/siew/venvs/lib/python3.5/site-packages/django/contrib/admin/options.py", line 979, in save_model
    obj.save()
  File "/home/siew/venvs/lib/python3.5/site-packages/django/db/models/base.py", line 807, in save
    force_update=force_update, update_fields=update_fields)
  File "/home/siew/venvs/lib/python3.5/site-packages/django/db/models/base.py", line 847, in save_base
    update_fields=update_fields, raw=raw, using=using,
  File "/home/siew/venvs/lib/python3.5/site-packages/django/dispatch/dispatcher.py", line 193, in send
    for receiver in self._live_receivers(sender)
  File "/home/siew/venvs/lib/python3.5/site-packages/django/dispatch/dispatcher.py", line 193, in <listcomp>
    for receiver in self._live_receivers(sender)
  File "/home/siew/djmatch/src/user/models.py", line 93, in create_invitation
    to_email = [email_target]
NameError: name 'email_target' is not defined
"POST /admin/user/invitation/add/ HTTP/1.1" 500 152248
Internal Server Error: /admin/user/invitation/add/
Traceback (most recent call last):
  File "/home/siew/venvs/lib/python3.5/site-packages/django/core/handlers/exception.py", line 41, in inner
    response = get_response(request)
  File "/home/siew/venvs/lib/python3.5/site-packages/django/core/handlers/base.py", line 187, in _get_response
    response = self.process_exception_by_middleware(e, request)
  File "/home/siew/venvs/lib/python3.5/site-packages/django/core/handlers/base.py", line 185, in _get_response
    response = wrapped_callback(request, *callback_args, **callback_kwargs)
  File "/home/siew/venvs/lib/python3.5/site-packages/django/contrib/admin/options.py", line 551, in wrapper
    return self.admin_site.admin_view(view)(*args, **kwargs)
  File "/home/siew/venvs/lib/python3.5/site-packages/django/utils/decorators.py", line 149, in _wrapped_view
    response = view_func(request, *args, **kwargs)
  File "/home/siew/venvs/lib/python3.5/site-packages/django/views/decorators/cache.py", line 57, in _wrapped_view_func
    response = view_func(request, *args, **kwargs)
  File "/home/siew/venvs/lib/python3.5/site-packages/django/contrib/admin/sites.py", line 224, in inner
    return view(request, *args, **kwargs)
  File "/home/siew/venvs/lib/python3.5/site-packages/django/contrib/admin/options.py", line 1508, in add_view
    return self.changeform_view(request, None, form_url, extra_context)
  File "/home/siew/venvs/lib/python3.5/site-packages/django/utils/decorators.py", line 67, in _wrapper
    return bound_func(*args, **kwargs)
  File "/home/siew/venvs/lib/python3.5/site-packages/django/utils/decorators.py", line 149, in _wrapped_view
    response = view_func(request, *args, **kwargs)
  File "/home/siew/venvs/lib/python3.5/site-packages/django/utils/decorators.py", line 63, in bound_func
    return func.__get__(self, type(self))(*args2, **kwargs2)
  File "/home/siew/venvs/lib/python3.5/site-packages/django/contrib/admin/options.py", line 1408, in changeform_view
    return self._changeform_view(request, object_id, form_url, extra_context)
  File "/home/siew/venvs/lib/python3.5/site-packages/django/contrib/admin/options.py", line 1448, in _changeform_view
    self.save_model(request, new_object, form, not add)
  File "/home/siew/venvs/lib/python3.5/site-packages/django/contrib/admin/options.py", line 979, in save_model
    obj.save()
  File "/home/siew/venvs/lib/python3.5/site-packages/django/db/models/base.py", line 807, in save
    force_update=force_update, update_fields=update_fields)
  File "/home/siew/venvs/lib/python3.5/site-packages/django/db/models/base.py", line 847, in save_base
    update_fields=update_fields, raw=raw, using=using,
  File "/home/siew/venvs/lib/python3.5/site-packages/django/dispatch/dispatcher.py", line 193, in send
    for receiver in self._live_receivers(sender)
  File "/home/siew/venvs/lib/python3.5/site-packages/django/dispatch/dispatcher.py", line 193, in <listcomp>
    for receiver in self._live_receivers(sender)
  File "/home/siew/djmatch/src/user/models.py", line 95, in create_invitation
    msg = EmailMultiAlternatives(subject, text_content, from_email, to_email)
NameError: name 'EmailMultiAlternatives' is not defined
"POST /admin/user/invitation/add/ HTTP/1.1" 500 152592
Internal Server Error: /user/invitation/b99f3ce0-d73e-4b0d-93b6-37d3e09d171b/
Traceback (most recent call last):
  File "/home/siew/venvs/lib/python3.5/site-packages/django/core/handlers/exception.py", line 41, in inner
    response = get_response(request)
  File "/home/siew/venvs/lib/python3.5/site-packages/django/core/handlers/base.py", line 187, in _get_response
    response = self.process_exception_by_middleware(e, request)
  File "/home/siew/venvs/lib/python3.5/site-packages/django/core/handlers/base.py", line 185, in _get_response
    response = wrapped_callback(request, *callback_args, **callback_kwargs)
  File "/home/siew/venvs/lib/python3.5/site-packages/django/views/generic/base.py", line 68, in view
    return self.dispatch(request, *args, **kwargs)
  File "/home/siew/venvs/lib/python3.5/site-packages/django/views/generic/base.py", line 88, in dispatch
    return handler(request, *args, **kwargs)
  File "/home/siew/venvs/lib/python3.5/site-packages/django/views/generic/edit.py", line 217, in post
    return super(BaseCreateView, self).post(request, *args, **kwargs)
  File "/home/siew/venvs/lib/python3.5/site-packages/django/views/generic/edit.py", line 183, in post
    return self.form_valid(form)
  File "/home/siew/djmatch/src/user/views/staffs.py", line 34, in form_valid
    user = authenticate(self.request,email=obj.email, password=raw_password)
NameError: name 'authenticate' is not defined
"POST /user/invitation/b99f3ce0-d73e-4b0d-93b6-37d3e09d171b/ HTTP/1.1" 500 99735
Internal Server Error: /user/invitation/b99f3ce0-d73e-4b0d-93b6-37d3e09d171b/
Traceback (most recent call last):
  File "/home/siew/venvs/lib/python3.5/site-packages/django/core/handlers/exception.py", line 41, in inner
    response = get_response(request)
  File "/home/siew/venvs/lib/python3.5/site-packages/django/core/handlers/base.py", line 187, in _get_response
    response = self.process_exception_by_middleware(e, request)
  File "/home/siew/venvs/lib/python3.5/site-packages/django/core/handlers/base.py", line 185, in _get_response
    response = wrapped_callback(request, *callback_args, **callback_kwargs)
  File "/home/siew/venvs/lib/python3.5/site-packages/django/views/generic/base.py", line 68, in view
    return self.dispatch(request, *args, **kwargs)
  File "/home/siew/venvs/lib/python3.5/site-packages/django/views/generic/base.py", line 88, in dispatch
    return handler(request, *args, **kwargs)
  File "/home/siew/venvs/lib/python3.5/site-packages/django/views/generic/edit.py", line 217, in post
    return super(BaseCreateView, self).post(request, *args, **kwargs)
  File "/home/siew/venvs/lib/python3.5/site-packages/django/views/generic/edit.py", line 182, in post
    if form.is_valid():
  File "/home/siew/venvs/lib/python3.5/site-packages/django/forms/forms.py", line 183, in is_valid
    return self.is_bound and not self.errors
  File "/home/siew/venvs/lib/python3.5/site-packages/django/forms/forms.py", line 175, in errors
    self.full_clean()
  File "/home/siew/venvs/lib/python3.5/site-packages/django/forms/forms.py", line 384, in full_clean
    self._clean_fields()
  File "/home/siew/venvs/lib/python3.5/site-packages/django/forms/forms.py", line 405, in _clean_fields
    value = getattr(self, 'clean_%s' % name)()
  File "/home/siew/djmatch/src/user/forms.py", line 60, in clean_email
    raise forms.ValidationError(self.error_messages['duplicate_email'])
KeyError: 'duplicate_email'
"POST /user/invitation/b99f3ce0-d73e-4b0d-93b6-37d3e09d171b/ HTTP/1.1" 500 114124
Internal Server Error: /project/create/
Traceback (most recent call last):
  File "/home/siew/venvs/lib/python3.5/site-packages/django/core/handlers/exception.py", line 41, in inner
    response = get_response(request)
  File "/home/siew/venvs/lib/python3.5/site-packages/django/core/handlers/base.py", line 187, in _get_response
    response = self.process_exception_by_middleware(e, request)
  File "/home/siew/venvs/lib/python3.5/site-packages/django/core/handlers/base.py", line 185, in _get_response
    response = wrapped_callback(request, *callback_args, **callback_kwargs)
  File "/home/siew/venvs/lib/python3.5/site-packages/django/views/generic/base.py", line 68, in view
    return self.dispatch(request, *args, **kwargs)
  File "/home/siew/venvs/lib/python3.5/site-packages/django/contrib/auth/mixins.py", line 56, in dispatch
    return super(LoginRequiredMixin, self).dispatch(request, *args, **kwargs)
  File "/home/siew/venvs/lib/python3.5/site-packages/django/contrib/auth/mixins.py", line 115, in dispatch
    return self.handle_no_permission()
  File "/home/siew/djmatch/src/user/views/mixins.py", line 24, in handle_no_permission
    messages.add_message(self.request, messages.ERROR, self.error_message)
NameError: name 'messages' is not defined
"GET /project/create/ HTTP/1.1" 500 91156
Internal Server Error: /project/create/
Traceback (most recent call last):
  File "/home/siew/venvs/lib/python3.5/site-packages/django/core/handlers/exception.py", line 41, in inner
    response = get_response(request)
  File "/home/siew/venvs/lib/python3.5/site-packages/django/core/handlers/base.py", line 187, in _get_response
    response = self.process_exception_by_middleware(e, request)
  File "/home/siew/venvs/lib/python3.5/site-packages/django/core/handlers/base.py", line 185, in _get_response
    response = wrapped_callback(request, *callback_args, **callback_kwargs)
  File "/home/siew/venvs/lib/python3.5/site-packages/django/views/generic/base.py", line 68, in view
    return self.dispatch(request, *args, **kwargs)
  File "/home/siew/venvs/lib/python3.5/site-packages/django/contrib/auth/mixins.py", line 56, in dispatch
    return super(LoginRequiredMixin, self).dispatch(request, *args, **kwargs)
  File "/home/siew/venvs/lib/python3.5/site-packages/django/contrib/auth/mixins.py", line 115, in dispatch
    return self.handle_no_permission()
  File "/home/siew/djmatch/src/user/views/mixins.py", line 26, in handle_no_permission
    return redirect_to_login(self.request.get_full_path(), self.get_required_url(),"")
NameError: name 'redirect_to_login' is not defined
"GET /project/create/ HTTP/1.1" 500 91268
