Internal Server Error: /project/single/manga/
Traceback (most recent call last):
  File "/home/siew/venvs/lib/python3.5/site-packages/django/core/handlers/exception.py", line 41, in inner
    response = get_response(request)
  File "/home/siew/venvs/lib/python3.5/site-packages/django/core/handlers/base.py", line 217, in _get_response
    response = self.process_exception_by_middleware(e, request)
  File "/home/siew/venvs/lib/python3.5/site-packages/django/core/handlers/base.py", line 215, in _get_response
    response = response.render()
  File "/home/siew/venvs/lib/python3.5/site-packages/django/template/response.py", line 107, in render
    self.content = self.rendered_content
  File "/home/siew/venvs/lib/python3.5/site-packages/django/template/response.py", line 84, in rendered_content
    content = template.render(context, self._request)
  File "/home/siew/venvs/lib/python3.5/site-packages/django/template/backends/django.py", line 66, in render
    return self.template.render(context)
  File "/home/siew/venvs/lib/python3.5/site-packages/django/template/base.py", line 207, in render
    return self._render(context)
  File "/home/siew/venvs/lib/python3.5/site-packages/django/template/base.py", line 199, in _render
    return self.nodelist.render(context)
  File "/home/siew/venvs/lib/python3.5/site-packages/django/template/base.py", line 990, in render
    bit = node.render_annotated(context)
  File "/home/siew/venvs/lib/python3.5/site-packages/django/template/base.py", line 957, in render_annotated
    return self.render(context)
  File "/home/siew/venvs/lib/python3.5/site-packages/django/template/loader_tags.py", line 177, in render
    return compiled_parent._render(context)
  File "/home/siew/venvs/lib/python3.5/site-packages/django/template/base.py", line 199, in _render
    return self.nodelist.render(context)
  File "/home/siew/venvs/lib/python3.5/site-packages/django/template/base.py", line 990, in render
    bit = node.render_annotated(context)
  File "/home/siew/venvs/lib/python3.5/site-packages/django/template/base.py", line 957, in render_annotated
    return self.render(context)
  File "/home/siew/venvs/lib/python3.5/site-packages/django/template/defaulttags.py", line 458, in render
    url = reverse(view_name, args=args, kwargs=kwargs, current_app=current_app)
  File "/home/siew/venvs/lib/python3.5/site-packages/django/urls/base.py", line 91, in reverse
    return force_text(iri_to_uri(resolver._reverse_with_prefix(view, prefix, *args, **kwargs)))
  File "/home/siew/venvs/lib/python3.5/site-packages/django/urls/resolvers.py", line 497, in _reverse_with_prefix
    raise NoReverseMatch(msg)
django.urls.exceptions.NoReverseMatch: Reverse for 'project' not found. 'project' is not a valid view function or pattern name.
"GET /project/single/manga/ HTTP/1.1" 500 158809
Internal Server Error: /project/single/manga/
Traceback (most recent call last):
  File "/home/siew/venvs/lib/python3.5/site-packages/django/template/base.py", line 507, in parse
    compile_func = self.tags[command]
KeyError: 'endif'

During handling of the above exception, another exception occurred:

Traceback (most recent call last):
  File "/home/siew/venvs/lib/python3.5/site-packages/django/core/handlers/exception.py", line 41, in inner
    response = get_response(request)
  File "/home/siew/venvs/lib/python3.5/site-packages/django/core/handlers/base.py", line 217, in _get_response
    response = self.process_exception_by_middleware(e, request)
  File "/home/siew/venvs/lib/python3.5/site-packages/django/core/handlers/base.py", line 215, in _get_response
    response = response.render()
  File "/home/siew/venvs/lib/python3.5/site-packages/django/template/response.py", line 107, in render
    self.content = self.rendered_content
  File "/home/siew/venvs/lib/python3.5/site-packages/django/template/response.py", line 82, in rendered_content
    template = self.resolve_template(self.template_name)
  File "/home/siew/venvs/lib/python3.5/site-packages/django/template/response.py", line 64, in resolve_template
    return select_template(template, using=self.using)
  File "/home/siew/venvs/lib/python3.5/site-packages/django/template/loader.py", line 48, in select_template
    return engine.get_template(template_name)
  File "/home/siew/venvs/lib/python3.5/site-packages/django/template/backends/django.py", line 39, in get_template
    return Template(self.engine.get_template(template_name), self)
  File "/home/siew/venvs/lib/python3.5/site-packages/django/template/engine.py", line 162, in get_template
    template, origin = self.find_template(template_name)
  File "/home/siew/venvs/lib/python3.5/site-packages/django/template/engine.py", line 136, in find_template
    name, template_dirs=dirs, skip=skip,
  File "/home/siew/venvs/lib/python3.5/site-packages/django/template/loaders/base.py", line 44, in get_template
    contents, origin, origin.template_name, self.engine,
  File "/home/siew/venvs/lib/python3.5/site-packages/django/template/base.py", line 191, in __init__
    self.nodelist = self.compile_nodelist()
  File "/home/siew/venvs/lib/python3.5/site-packages/django/template/base.py", line 230, in compile_nodelist
    return parser.parse()
  File "/home/siew/venvs/lib/python3.5/site-packages/django/template/base.py", line 515, in parse
    raise self.error(token, e)
  File "/home/siew/venvs/lib/python3.5/site-packages/django/template/base.py", line 513, in parse
    compiled_result = compile_func(self, token)
  File "/home/siew/venvs/lib/python3.5/site-packages/django/template/loader_tags.py", line 312, in do_extends
    nodelist = parser.parse()
  File "/home/siew/venvs/lib/python3.5/site-packages/django/template/base.py", line 515, in parse
    raise self.error(token, e)
  File "/home/siew/venvs/lib/python3.5/site-packages/django/template/base.py", line 513, in parse
    compiled_result = compile_func(self, token)
  File "/home/siew/venvs/lib/python3.5/site-packages/django/template/loader_tags.py", line 255, in do_block
    nodelist = parser.parse(('endblock',))
  File "/home/siew/venvs/lib/python3.5/site-packages/django/template/base.py", line 509, in parse
    self.invalid_block_tag(token, command, parse_until)
  File "/home/siew/venvs/lib/python3.5/site-packages/django/template/base.py", line 565, in invalid_block_tag
    get_text_list(["'%s'" % p for p in parse_until], 'or'),
django.template.exceptions.TemplateSyntaxError: Invalid block tag on line 12: 'endif', expected 'endblock'. Did you forget to register or load this tag?
"GET /project/single/manga/ HTTP/1.1" 500 181810
Internal Server Error: /project/
Traceback (most recent call last):
  File "/home/siew/venvs/lib/python3.5/site-packages/django/template/base.py", line 507, in parse
    compile_func = self.tags[command]
KeyError: 'empty'

During handling of the above exception, another exception occurred:

Traceback (most recent call last):
  File "/home/siew/venvs/lib/python3.5/site-packages/django/core/handlers/exception.py", line 41, in inner
    response = get_response(request)
  File "/home/siew/venvs/lib/python3.5/site-packages/django/core/handlers/base.py", line 217, in _get_response
    response = self.process_exception_by_middleware(e, request)
  File "/home/siew/venvs/lib/python3.5/site-packages/django/core/handlers/base.py", line 215, in _get_response
    response = response.render()
  File "/home/siew/venvs/lib/python3.5/site-packages/django/template/response.py", line 107, in render
    self.content = self.rendered_content
  File "/home/siew/venvs/lib/python3.5/site-packages/django/template/response.py", line 82, in rendered_content
    template = self.resolve_template(self.template_name)
  File "/home/siew/venvs/lib/python3.5/site-packages/django/template/response.py", line 64, in resolve_template
    return select_template(template, using=self.using)
  File "/home/siew/venvs/lib/python3.5/site-packages/django/template/loader.py", line 48, in select_template
    return engine.get_template(template_name)
  File "/home/siew/venvs/lib/python3.5/site-packages/django/template/backends/django.py", line 39, in get_template
    return Template(self.engine.get_template(template_name), self)
  File "/home/siew/venvs/lib/python3.5/site-packages/django/template/engine.py", line 162, in get_template
    template, origin = self.find_template(template_name)
  File "/home/siew/venvs/lib/python3.5/site-packages/django/template/engine.py", line 136, in find_template
    name, template_dirs=dirs, skip=skip,
  File "/home/siew/venvs/lib/python3.5/site-packages/django/template/loaders/base.py", line 44, in get_template
    contents, origin, origin.template_name, self.engine,
  File "/home/siew/venvs/lib/python3.5/site-packages/django/template/base.py", line 191, in __init__
    self.nodelist = self.compile_nodelist()
  File "/home/siew/venvs/lib/python3.5/site-packages/django/template/base.py", line 230, in compile_nodelist
    return parser.parse()
  File "/home/siew/venvs/lib/python3.5/site-packages/django/template/base.py", line 515, in parse
    raise self.error(token, e)
  File "/home/siew/venvs/lib/python3.5/site-packages/django/template/base.py", line 513, in parse
    compiled_result = compile_func(self, token)
  File "/home/siew/venvs/lib/python3.5/site-packages/django/template/loader_tags.py", line 312, in do_extends
    nodelist = parser.parse()
  File "/home/siew/venvs/lib/python3.5/site-packages/django/template/base.py", line 515, in parse
    raise self.error(token, e)
  File "/home/siew/venvs/lib/python3.5/site-packages/django/template/base.py", line 513, in parse
    compiled_result = compile_func(self, token)
  File "/home/siew/venvs/lib/python3.5/site-packages/django/template/loader_tags.py", line 255, in do_block
    nodelist = parser.parse(('endblock',))
  File "/home/siew/venvs/lib/python3.5/site-packages/django/template/base.py", line 509, in parse
    self.invalid_block_tag(token, command, parse_until)
  File "/home/siew/venvs/lib/python3.5/site-packages/django/template/base.py", line 565, in invalid_block_tag
    get_text_list(["'%s'" % p for p in parse_until], 'or'),
django.template.exceptions.TemplateSyntaxError: Invalid block tag on line 73: 'empty', expected 'endblock'. Did you forget to register or load this tag?
"GET /project/?title=ff&company=&strict_id_summary=0&summary=&strict_id_keywords=0&deadline=&submit=Submit HTTP/1.1" 500 183475
Internal Server Error: /user/register/
Traceback (most recent call last):
  File "/home/siew/venvs/lib/python3.5/site-packages/django/core/handlers/exception.py", line 41, in inner
    response = get_response(request)
  File "/home/siew/venvs/lib/python3.5/site-packages/django/core/handlers/base.py", line 187, in _get_response
    response = self.process_exception_by_middleware(e, request)
  File "/home/siew/venvs/lib/python3.5/site-packages/django/core/handlers/base.py", line 185, in _get_response
    response = wrapped_callback(request, *callback_args, **callback_kwargs)
  File "/home/siew/venvs/lib/python3.5/site-packages/django/views/generic/base.py", line 68, in view
    return self.dispatch(request, *args, **kwargs)
  File "/home/siew/venvs/lib/python3.5/site-packages/django/views/generic/base.py", line 88, in dispatch
    return handler(request, *args, **kwargs)
  File "/home/siew/venvs/lib/python3.5/site-packages/django/views/generic/edit.py", line 217, in post
    return super(BaseCreateView, self).post(request, *args, **kwargs)
  File "/home/siew/venvs/lib/python3.5/site-packages/django/views/generic/edit.py", line 182, in post
    if form.is_valid():
  File "/home/siew/venvs/lib/python3.5/site-packages/django/forms/forms.py", line 183, in is_valid
    return self.is_bound and not self.errors
  File "/home/siew/venvs/lib/python3.5/site-packages/django/forms/forms.py", line 175, in errors
    self.full_clean()
  File "/home/siew/venvs/lib/python3.5/site-packages/django/forms/forms.py", line 384, in full_clean
    self._clean_fields()
  File "/home/siew/venvs/lib/python3.5/site-packages/django/forms/forms.py", line 405, in _clean_fields
    value = getattr(self, 'clean_%s' % name)()
  File "/home/siew/djmatch/src/user/forms.py", line 133, in clean_email
    raise forms.ValidationError(self.error_messages['duplicate_email'])
KeyError: 'duplicate_email'
"POST /user/register/ HTTP/1.1" 500 115465
Internal Server Error: /user/profile/password-change/
Traceback (most recent call last):
  File "/home/siew/venvs/lib/python3.5/site-packages/django/core/handlers/exception.py", line 41, in inner
    response = get_response(request)
  File "/home/siew/venvs/lib/python3.5/site-packages/django/core/handlers/base.py", line 198, in _get_response
    "returned None instead." % (callback.__module__, view_name)
ValueError: The view user.views.views.UserProfilePasswordView didn't return an HttpResponse object. It returned None instead.
"POST /user/profile/password-change/ HTTP/1.1" 500 73029
Internal Server Error: /user/profile/password-change/
Traceback (most recent call last):
  File "/home/siew/venvs/lib/python3.5/site-packages/django/core/handlers/exception.py", line 41, in inner
    response = get_response(request)
  File "/home/siew/venvs/lib/python3.5/site-packages/django/core/handlers/base.py", line 198, in _get_response
    "returned None instead." % (callback.__module__, view_name)
ValueError: The view user.views.views.UserProfilePasswordView didn't return an HttpResponse object. It returned None instead.
"POST /user/profile/password-change/ HTTP/1.1" 500 73047
Internal Server Error: /user/profile/preferences/
Traceback (most recent call last):
  File "/home/siew/venvs/lib/python3.5/site-packages/django/core/handlers/exception.py", line 41, in inner
    response = get_response(request)
  File "/home/siew/venvs/lib/python3.5/site-packages/django/core/handlers/base.py", line 187, in _get_response
    response = self.process_exception_by_middleware(e, request)
  File "/home/siew/venvs/lib/python3.5/site-packages/django/core/handlers/base.py", line 185, in _get_response
    response = wrapped_callback(request, *callback_args, **callback_kwargs)
  File "/home/siew/venvs/lib/python3.5/site-packages/django/views/generic/base.py", line 68, in view
    return self.dispatch(request, *args, **kwargs)
  File "/home/siew/venvs/lib/python3.5/site-packages/django/contrib/auth/mixins.py", line 56, in dispatch
    return super(LoginRequiredMixin, self).dispatch(request, *args, **kwargs)
  File "/home/siew/venvs/lib/python3.5/site-packages/django/contrib/auth/mixins.py", line 116, in dispatch
    return super(UserPassesTestMixin, self).dispatch(request, *args, **kwargs)
  File "/home/siew/venvs/lib/python3.5/site-packages/django/views/generic/base.py", line 88, in dispatch
    return handler(request, *args, **kwargs)
  File "/home/siew/venvs/lib/python3.5/site-packages/django/views/generic/edit.py", line 236, in get
    return super(BaseUpdateView, self).get(request, *args, **kwargs)
  File "/home/siew/venvs/lib/python3.5/site-packages/django/views/generic/edit.py", line 174, in get
    return self.render_to_response(self.get_context_data())
  File "/home/siew/djmatch/src/user/views/views.py", line 176, in get_context_data
    context = super(UserProfilePreferenceView, self).get_context_data(**kwargs)
  File "/home/siew/venvs/lib/python3.5/site-packages/django/views/generic/edit.py", line 93, in get_context_data
    kwargs['form'] = self.get_form()
  File "/home/siew/venvs/lib/python3.5/site-packages/django/views/generic/edit.py", line 45, in get_form
    return form_class(**self.get_form_kwargs())
  File "/home/siew/djmatch/src/user/forms.py", line 287, in __init__
    self.helper.form_class = 'form-horizontal container'
TypeError: add_input() missing 1 required positional argument: 'input_object'
"GET /user/profile/preferences/ HTTP/1.1" 500 120652
